Workbook

Sheet last run
A1: Sample Label | B1: Samples | C1: Average response time (ms) | D1: Min(ms) | E1: Max(ms) | F1: Std. Dev | G1: Error | H1: Throughput | I1: Kb/sec | J1: Avg. Bytes | K1: Users
A2: [GET] Home Page | B2: 10 | C2: 275 | D2: 229 | E2: 439 | F2: 66.761965 | G2: 0 | H2: 0.043868115 | I2: 9.1820291 | J2: 214333.3 | K2: 1
A3: [GET] Products Page | B3: 5 | C3: 405 | D3: 332 | E3: 458 | F3: 45.378409 | G3: 0 | H3: 0.023310241 | I3: 3.7568004 | J3: 165033.2 | K3: 1
A4: [GET] Blog Page | B4: 5 | C4: 238 | D4: 216 | E4: 263 | F4: 16.74037 | G4: 0 | H4: 0.023320134 | I4: 4.8697268 | J4: 213832.4 | K4: 1
A5: [GET] Contact Page | B5: 5 | C5: 180 | D5: 157 | E5: 194 | F5: 14.305244 | G5: 0 | H5: 0.023325574 | I5: 1.0868852 | J5: 47714.6 | K5: 1
A6: [GET] About Page | B6: 5 | C6: 194 | D6: 177 | E6: 227 | F6: 18.216476 | G6: 0 | H6: 0.023322418 | I6: 1.0871117 | J6: 47731 | K6: 1
A7: [GET] Search <bag> | B7: 5 | C7: 312 | D7: 281 | E7: 378 | F7: 35.797207 | G7: 0 | H7: 0.023306655 | I7: 1.5266815 | J7: 67076.2 | K7: 1
A8: [GET] Category | B8: 20 | C8: 305 | D8: 260 | E8: 428 | F8: 38.438392 | G8: 0 | H8: 0.082419507 | I8: 4.1046082 | J8: 50996.65 | K8: 1
A9: [GET] Product Details | B9: 20 | C9: 244 | D9: 209 | E9: 312 | F9: 24.808466 | G9: 0 | H9: 0.08242664 | I9: 7.5196399 | J9: 93417.75 | K9: 1
A10: [POST] Add to cart | B10: 20 | C10: 533 | D10: 443 | E10: 985 | F10: 131.72391 | G10: 0 | H10: 0.082322482 | I10: 5.4657063 | J10: 67987.3 | K10: 1
A11: [GET] View Cart | B11: 20 | C11: 300 | D11: 225 | E11: 428 | F11: 58.714053 | G11: 0 | H11: 0.082558317 | I11: 4.0024175 | J11: 49643.4 | K11: 1
A12: TOTAL | B12: 115 | C12: 322 | D12: 157 | E12: 985 | F12: 125.95807 | G12: 0 | H12: 0.43309444 | I12: 37.113031 | J12: 87749.322 | K12: 1
A14: [GET] Home Page | B14: 50 | C14: 305 | D14: 213 | E14: 500 | F14: 74.038736 | G14: 0 | H14: 0.2028414 | I14: 42.456552 | J14: 214332.52 | K14: 5
... A48: TOTAL | B48: 1172 | C48: 2269 | D48: 18 | E48: 28366 | F48: 2802.193 | G48: 0.0034129693 | H48: 3.2651879 | I48: 290.02886 | J48: 90956.346 | K48: 20

Sheet ResponseTime
A1: Average response time (ms) | B1: 1 | C1: 5 | D1: 10 | E1: 20 | F1: 50
A2: [GET] Home Page | B2: =SUMIFS('last run'!$C:$C, 'last run'!$A:$A, $A2, 'last run'!$K:$K, B$1) -> 275 | C2: =SUMIFS('last run'!$C:$C, 'last run'!$A:$A, $A2, 'last run'!$K:$K, C$1) -> 305 | D2: =SUMIFS('last run'!$C:$C, 'last run'!$A:$A, $A2, 'last run'!$K:$K, D$1) -> 544 | E2: =SUMIFS('last run'!$C:$C, 'last run'!$A:$A, $A2, 'last run'!$K:$K, E$1) -> 1693
A3: [GET] Products Page | B3: =SUMIFS('last run'!$C:$C, 'last run'!$A:$A, $A3, 'last run'!$K:$K, B$1) -> 405 | C3: =SUMIFS('last run'!$C:$C, 'last run'!$A:$A, $A3, 'last run'!$K:$K, C$1) -> 453 | D3: =SUMIFS('last run'!$C:$C, 'last run'!$A:$A, $A3, 'last run'!$K:$K, D$1) -> 710 | E3: =SUMIFS('last run'!$C:$C, 'last run'!$A:$A, $A3, 'last run'!$K:$K, E$1) -> 2112
A4: [GET] Blog Page | B4: =SUMIFS('last run'!$C:$C, 'last run'!$A:$A, $A4, 'last run'!$K:$K, B$1) -> 238 | C4: =SUMIFS('last run'!$C:$C, 'last run'!$A:$A, $A4, 'last run'!$K:$K, C$1) -> 246 | D4: =SUMIFS('last run'!$C:$C, 'last run'!$A:$A, $A4, 'last run'!$K:$K, D$1) -> 429 | E4: =SUMIFS('last run'!$C:$C, 'last run'!$A:$A, $A4, 'last run'!$K:$K, E$1) -> 1359
A5: [GET] Contact Page | B5: =SUMIFS('last run'!$C:$C, 'last run'!$A:$A, $A5, 'last run'!$K:$K, B$1) -> 180 | C5: =SUMIFS('last run'!$C:$C, 'last run'!$A:$A, $A5, 'last run'!$K:$K, C$1) -> 212 | D5: =SUMIFS('last run'!$C:$C, 'last run'!$A:$A, $A5, 'last run'!$K:$K, D$1) -> 404 | E5: =SUMIFS('last run'!$C:$C, 'last run'!$A:$A, $A5, 'last run'!$K:$K, E$1) -> 1105
A6: [GET] About Page | B6: =SUMIFS('last run'!$C:$C, 'last run'!$A:$A, $A6, 'last run'!$K:$K, B$1) -> 194 | C6: =SUMIFS('last run'!$C:$C, 'last run'!$A:$A, $A6, 'last run'!$K:$K, C$1) -> 220 | D6: =SUMIFS('last run'!$C:$C, 'last run'!$A:$A, $A6, 'last run'!$K:$K, D$1) -> 468 | E6: =SUMIFS('last run'!$C:$C, 'last run'!$A:$A, $A6, 'last run'!$K:$K, E$1) -> 1184
A7: [GET] Search <bag> | B7: =SUMIFS('last run'!$C:$C, 'last run'!$A:$A, $A7, 'last run'!$K:$K, B$1) -> 312 | C7: =SUMIFS('last run'!$C:$C, 'last run'!$A:$A, $A7, 'last run'!$K:$K, C$1) -> 338 | D7: =SUMIFS('last run'!$C:$C, 'last run'!$A:$A, $A7, 'last run'!$K:$K, D$1) -> 633 | E7: =SUMIFS('last run'!$C:$C, 'last run'!$A:$A, $A7, 'last run'!$K:$K, E$1) -> 2521
A8: [GET] Category | B8: =SUMIFS('last run'!$C:$C, 'last run'!$A:$A, $A8, 'last run'!$K:$K, B$1) -> 305 | C8: =SUMIFS('last run'!$C:$C, 'last run'!$A:$A, $A8, 'last run'!$K:$K, C$1) -> 348 | D8: =SUMIFS('last run'!$C:$C, 'last run'!$A:$A, $A8, 'last run'!$K:$K, D$1) -> 629 | E8: =SUMIFS('last run'!$C:$C, 'last run'!$A:$A, $A8, 'last run'!$K:$K, E$1) -> 2564
A9: [GET] Product Details | B9: =SUMIFS('last run'!$C:$C, 'last run'!$A:$A, $A9, 'last run'!$K:$K, B$1) -> 244 | C9: =SUMIFS('last run'!$C:$C, 'last run'!$A:$A, $A9, 'last run'!$K:$K, C$1) -> 301 | D9: =SUMIFS('last run'!$C:$C, 'last run'!$A:$A, $A9, 'last run'!$K:$K, D$1) -> 551 | E9: =SUMIFS('last run'!$C:$C, 'last run'!$A:$A, $A9, 'last run'!$K:$K, E$1) -> 2134
A10: [POST] Add to cart | B10: =SUMIFS('last run'!$C:$C, 'last run'!$A:$A, $A10, 'last run'!$K:$K, B$1) -> 533 | C10: =SUMIFS('last run'!$C:$C, 'last run'!$A:$A, $A10, 'last run'!$K:$K, C$1) -> 583 | D10: =SUMIFS('last run'!$C:$C, 'last run'!$A:$A, $A10, 'last run'!$K:$K, D$1) -> 1069 | E10: =SUMIFS('last run'!$C:$C, 'last run'!$A:$A, $A10, 'last run'!$K:$K, E$1) -> 3612
A11: [GET] View Cart | B11: =SUMIFS('last run'!$C:$C, 'last run'!$A:$A, $A11, 'last run'!$K:$K, B$1) -> 300 | C11: =SUMIFS('last run'!$C:$C, 'last run'!$A:$A, $A11, 'last run'!$K:$K, C$1) -> 336 | D11: =SUMIFS('last run'!$C:$C, 'last run'!$A:$A, $A11, 'last run'!$K:$K, D$1) -> 613 | E11: =SUMIFS('last run'!$C:$C, 'last run'!$A:$A, $A11, 'last run'!$K:$K, E$1) -> 2127

Sheet Other runs
A1: Average response time (ms) | B1: 9 dec | C1: 10 dec | D1: 11 dec | E1: 12 dec | F1: 13 dec
A2: Home page | B2: 17187 | C2: 10540 | D2: 9668
A3: Wishlist page | B3: 4005 | C3: 3848 | D3: 3752
A4: Last minute offers | B4: 5984 | C4: 5263 | D4: 3939
A5: Ski page | B5: 6042 | C5: 4275 | D5: 4351
A6: Promotion Page | B6: 6685 | C6: 5548 | D6: 5190
A7: Tours Page | B7: 6054 | C7: 5220 | D7: 4872
A8: Charters Page | B8: 4858 | C8: 4007 | D8: 3618
A9: Destination Page | B9: 15998 | C9: 14381 | D9: 13789
A10: Airline Tickets Page | B10: 4536 | C10: 3876 | D10: 3546
A11: Search a country | B11: 4189 | C11: 4064
A12: Search Results (destination) | B12: 7222 | C12: 8054
A13: Vacation Details (destination) | B13: 4165 | C13: 3412
A14: Search Results (tours) | B14: 2691 | C14: 2475
A15: Vacation Details (tours) | B15: 2910 | C15: 2721
A16: Search Results (last minute) | B16: 3728 | C16: 3696
A17: Vacation Details (ski) | B17: 2945 | C17: 1601
A18: Search Results (airline) | B18: 2642 | C18: 1939
B20: =SUM(B2:B18) -> 101841 | C20: =SUM(C2:C18) -> 84920
A21: 100 useri | C21: =100-(C20*100/B20) -> 16.615116

Sheet Throughput
A1: Throughput | B1: 1 | C1: 10 | D1: 100 | E1: 500 | F1: 1000
A2: Home page | B2: 0.0089553656 | C2: 0.047092021
A3: Wishlist page | B3: 0.0089955319 | C3: 0.047460552
A4: Last minute offers | B4: 0.0089879885 | C4: 0.047458908
A5: Ski page | B5: 0.008991221 | C5: 0.047468212
A6: Promotion Page | B6: 0.0089822 | C6: 0.047391343
A7: Destination Page | B7: 0.0088874116 | C7: 0.047101958
A8: Tours Page | B8: 0.0089899762 | C8: 0.047386111
A9: Charters Page | B9: 0.008996155 | C9: 0.047388626
A10: Get country names | B10: 0.0089013349 | C10: 0.047090224
A11: Search a country | B11: 0.0090141414 | C11: 0.047355346
A12: Destination Details | B12: 0.0072151764 | C12: 0.043863288
A13: Visit Destination Page | B13: 0.0072419293 | C13: 0.043928591

Sheet Labels and links
A1: Label | B1: URL | C1: Example
A2: Home page | B2: wwwnew.tui.pl
A3: Wishlist page | B3: / | C3: wwwnew.tui.pl
A4: Last minute offers | B4: /wishlist | C4: /wishlist
A5: Ski page | B5: /search/lastMinute | C5: /search/lastMinute
A6: Promotion Page | B6: /narty | C6: /narty
A7: Tours Page | B7: /promocje | C7: /promocje
A8: Charters Page | B8: /wycieczki-objazdowe | C8: /wycieczki-objazdowe
A9: Destination Page | B9: /bilety-lotnicze | C9: /bilety-lotnicze
A10: Airline Tickets Page | B10: /wypoczynek | C10: /wypoczynek
A11: Search a country | B11: /textsearch/?text=${countryName} | C11: /textsearch/?text=Tunezja
A12: Search Results (destination) | B12: /destination-details/${countryCode} | C12: /search/summer?q=%3Aprice-asc%3Aduration%3A6%3BTO%3B8%3ActAdult%3A2%3ActChild%3A0%3BTO%3BnoLimit%3AminPeople%3AnoLimit%3BTO%3B4%3AbyPlane%3AT&useStartDateVariation=false
A13: Vacation Details (destination) | B13: /${destLink} | C13: /wypoczynek/Hiszpania/Teneryfa/hotele;show,TFS,blue-sea-lagos-de-cesar-tfs36005/transport:plane/destination:TFS/date:20141211-20141218/duration:7/ctAdult:2/departure:POZ/room:JSX1/food:H/promotion:0147/offerCode:POZTFS2014121120141218TFS36005JSX1H20147
A14: Search Results (tours) | B14: /search/tour?q=${searchFilters} | C14: /search/tour?q=%3Aprice-asc%3Aduration%3A6%3BTO%3B8%3ActAdult%3A2%3ActChild%3A0%3BTO%3BnoLimit%3AminPeople%3AnoLimit%3BTO%3B4%3AbyPlane%3AT&useStartDateVariation=false
... A19: Search Results (airline) | B19: /chartersListPage?${searchFilters} | C19: /chartersListPage?q=%3AdepartureDateTime-asc%3AdepartureFrom%3APOZ%3AdepartureTo%3ADLM%3AdepartureDate%3A20150511T000000%3BTO%3B20150511T235959%3AreturnDate%3A20150608T000000%3BTO%3B20150608T235959%3AfreeSeats%3A1%3BTO%3BnoLimit%3AcharterType%3ABOTH

Sheet 8 dec
A1: Sample Label | B1: Samples | C1: Average response time (ms) | D1: Min(ms) | E1: Max(ms) | F1: Std. Dev | G1: Error | H1: Throughput | I1: Kb/sec | J1: Avg. Bytes
A2: [GET] Home page | B2: 10 | C2: 10433 | D2: 10131 | E2: 10762 | F2: 247.5327 | G2: 0 | H2: 0.0061064787 | I2: 6.1451761 | J2: 1030489.2
A3: [GET] Wishlist page | B3: 10 | C3: 5459 | D3: 5242 | E3: 6020 | F3: 220.01873 | G3: 0 | H3: 0.00612437 | I3: 0.31122206 | J3: 52036.6
A4: [GET] Last minute offers | B4: 10 | C4: 5778 | D4: 5597 | E4: 6109 | F4: 160.1232 | G4: 0 | H4: 0.0061227914 | I4: 0.31572317 | J4: 52802.8
A5: [GET] Ski page | B5: 10 | C5: 5225 | D5: 5038 | E5: 5396 | F5: 108.03685 | G5: 0 | H5: 0.0061260621 | I5: 0.34883975 | J5: 58310.2
A6: [GET] Promotion Page | B6: 10 | C6: 6105 | D6: 5910 | E6: 6483 | F6: 174.73835 | G6: 0 | H6: 0.0061240775 | I6: 0.32039092 | J6: 53572.2
A7: [GET] Tours Page | B7: 10 | C7: 5735 | D7: 5505 | E7: 6014 | F7: 165.89457 | G7: 0 | H7: 0.0061254279 | I7: 0.31608584 | J7: 52840.7
A8: [GET] Charters Page | B8: 10 | C8: 5059 | D8: 4849 | E8: 5158 | F8: 101.58071 | G8: 0 | H8: 0.0061282959 | I8: 0.32909428 | J8: 54989.6
A9: [GET] Destination Page | B9: 10 | C9: 18160 | D9: 17843 | E9: 18669 | F9: 254.6107 | G9: 0 | H9: 0.0060801103 | I9: 2.2770963 | J9: 383504
A10: [GET] Search a country | B10: 10 | C10: 5385 | D10: 5223 | E10: 5594 | F10: 106.18479 | G10: 0 | H10: 0.0061285851 | I10: 0.3184171 | J10: 53203
A11: [GET] Destination Details | B11: 8 | C11: 6371 | D11: 6191 | E11: 6499 | F11: 106.86908 | G11: 0 | H11: 0.0049005735 | I11: 0.28846742 | J11: 60276.75
A12: [GET] Visit Destination Page | B12: 8 | C12: 3520 | D12: 78 | E12: 4587 | F12: 1326.3112 | G12: 0.125 | H12: 0.0049072529 | I12: 0.26273391 | J12: 54824.875
A13: [Transaction] Search by an available country name | B13: 10 | C13: 67511 | D13: 43308 | E13: 74431 | F13: 12055.24 | G13: 0.1 | H13: 0.0058809138 | I13: 3.0368735 | J13: 528788.3
... A57: TOTAL | B57: 11804 | C57: 21513 | D57: 162 | E57: 215908 | F57: 26701.76 | G57: 0.0054218909 | H57: 4.1029591 | I57: 831.23469 | J57: 207456.2

Sheet 9 dec
A1: Sample Label | B1: Samples | C1: Average response time (ms) | D1: Min(ms) | E1: Max(ms) | F1: Std. Dev | G1: Error | H1: Throughput | I1: Kb/sec | J1: Avg. Bytes
A2: [GET] Home page | B2: 10 | C2: 8808 | D2: 8573 | E2: 9432 | F2: 234.09761 | G2: 0 | H2: 0.011394557 | I2: 11.485938 | J2: 1032212.2 | L2: 1
A3: [GET] Wishlist page | B3: 10 | C3: 3588 | D3: 3379 | E3: 3832 | F3: 139.04118 | G3: 0 | H3: 0.011463525 | I3: 0.58335127 | J3: 52108.9
A4: [GET] Last minute offers | B4: 10 | C4: 4250 | D4: 4130 | E4: 4503 | F4: 114.30486 | G4: 0 | H4: 0.011456919 | I4: 0.5935389 | J4: 53049.5
A5: [GET] Ski page | B5: 10 | C5: 3565 | D5: 3447 | E5: 3688 | F5: 70.792655 | G5: 0 | H5: 0.011465773 | I5: 0.65546263 | J5: 58538.9
A6: [GET] Promotion Page | B6: 10 | C6: 4208 | D6: 4099 | E6: 4313 | F6: 64.768511 | G6: 0 | H6: 0.011458153 | I6: 0.60165934 | J6: 53769.5
A7: [GET] Tours Page | B7: 10 | C7: 4161 | D7: 4066 | E7: 4329 | F7: 71.02225 | G7: 0 | H7: 0.01145923 | I7: 0.59300395 | J7: 52991
A8: [GET] Charters Page | B8: 10 | C8: 3369 | D8: 3271 | E8: 3426 | F8: 51.515143 | G8: 0 | H8: 0.011470692 | I8: 0.61672443 | J8: 55055.6
A9: [GET] Destination Page | B9: 10 | C9: 11882 | D9: 11446 | E9: 12174 | F9: 218.11614 | G9: 0 | H9: 0.011363791 | I9: 4.2615327 | J9: 384010
A10: [GET] Airline Tickets Page | B10: 10 | C10: 3369 | D10: 3257 | E10: 3427 | F10: 52.328291 | G10: 0 | H10: 0.011477064 | I10: 0.61706702 | J10: 55055.6
A11: [GET] Search a country | B11: 10 | C11: 3481 | D11: 3336 | E11: 3580 | F11: 79.941479 | G11: 0 | H11: 0.011477643 | I11: 0.5974528 | J11: 53302.9
A12: [GET] Search Results (destination) | B12: 10 | C12: 5832 | D12: 66 | E12: 7252 | F12: 1943.55 | G12: 0 | H12: 0.011441189 | I12: 0.61466785 | J12: 55013.5
A13: [GET] Visit Vacation Details (destination) | B13: 9 | C13: 2641 | D13: 2433 | E13: 2977 | F13: 168.29919 | G13: 0 | H13: 0.010343769 | I13: 0.62750854 | J13: 62121.333
A14: [GET] Search Results (tours) | B14: 10 | C14: 2016 | D14: 1886 | E14: 2095 | F14: 56.601767 | G14: 0 | H14: 0.011500056 | I14: 0.66697179 | J14: 59389.2
... A19: TOTAL | B19: 309 | C19: 3577 | D19: 0 | E19: 13245 | F19: 3277.8527 | G19: 0.019417476 | H19: 0.32121985 | I19: 27.343352 | J19: 87166.447
A21: [GET] Home page | B21: 30 | C21: 10856 | D21: 8711 | E21: 12739 | F21: 946.38669 | G21: 0 | H21: 0.044190236 | I21: 44.544509 | J21: 1032209.4 | L21: 10
A22: [GET] Wishlist page | B22: 30 | C22: 3574 | D22: 3395 | E22: 3862 | F22: 107.95269 | G22: 0 | H22: 0.044622339 | I22: 2.2707599 | J22: 52109.733
A23: [GET] Last minute offers | B23: 30 | C23: 4253 | D23: 4006 | E23: 4612 | F23: 134.98432 | G23: 0 | H23: 0.044576788 | I23: 2.3093925 | J23: 53050.433
A24: [GET] Ski page | B24: 30 | C24: 3609 | D24: 3457 | E24: 3910 | F24: 97.190535 | G24: 0 | H24: 0.044627516 | I24: 2.5512296 | J24: 58539.2
A25: [GET] Promotion Page | B25: 30 | C25: 4238 | D25: 4051 | E25: 4472 | F25: 88.127969 | G25: 0 | H25: 0.04458931 | I25: 2.3413887 | J25: 53770.333
A26: [GET] Tours Page | B26: 30 | C26: 4181 | D26: 3959 | E26: 4906 | F26: 169.26911 | G26: 0 | H26: 0.044605686 | I26: 2.3083515 | J26: 52992.167
A27: [GET] Charters Page | B27: 30 | C27: 3389 | D27: 3240 | E27: 3583 | F27: 69.702893 | G27: 0 | H27: 0.044651296 | I27: 2.4007194 | J27: 55056.333
A28: [GET] Destination Page | B28: 30 | C28: 12177 | D28: 11768 | E28: 12594 | F28: 194.97989 | G28: 0 | H28: 0.044085296 | I28: 16.532761 | J28: 384018
A29: [GET] Airline Tickets Page | B29: 30 | C29: 3367 | D29: 3241 | E29: 3517 | F29: 74.857969 | G29: 0 | H29: 0.044677229 | I29: 2.4021137 | J29: 55056.333
A30: [GET] Search a country | B30: 30 | C30: 3547 | D30: 3381 | E30: 3720 | F30: 75.524249 | G30: 0 | H30: 0.044665855 | I30: 2.3442682 | J30: 53744.2
A31: [GET] Search Results (destination) | B31: 30 | C31: 7014 | D31: 6051 | E31: 8472 | F31: 543.3081 | G31: 0 | H31: 0.044407405 | I31: 2.6446605 | J31: 60983.8
A32: [GET] Visit Vacation Details (destination) | B32: 30 | C32: 2671 | D32: 2400 | E32: 3415 | F32: 265.43304 | G32: 0 | H32: 0.044634156 | I32: 2.7141257 | J32: 62267.667
A33: [GET] Search Results (tours) | B33: 30 | C33: 2054 | D33: 1839 | E33: 4414 | F33: 444.76651 | G33: 0 | H33: 0.044705791 | I33: 2.5928355 | J33: 59389.7
... A38: TOTAL | B38: 930 | C38: 8397 | D38: 0 | E38: 63854 | F38: 13781.265 | G38: 0.012903226 | H38: 0.94634528 | I38: 81.011607 | J38: 87659.217
A40: 100 users 18:10 - 19:00 server time
A41: [GET] Home page | B41: 854 | C41: 17187 | D41: 2066 | E41: 43032 | F41: 6313.7347 | G41: 0 | H41: 0.2889441 | I41: 288.88361 | J41: 1023785.6
A42: [GET] Wishlist page | B42: 837 | C42: 4005 | D42: 514 | E42: 6692 | F42: 448.2909 | G42: 0 | H42: 0.28688789 | I42: 14.585769 | J42: 52061.547
A43: [GET] Last minute offers | B43: 829 | C43: 5984 | D43: 176 | E43: 11671 | F43: 1459.2777 | G43: 0 | H43: 0.28502567 | I43: 14.687965 | J43: 52768.848
A44: [GET] Ski page | B44: 819 | C44: 6042 | D44: 249 | E44: 15856 | F44: 2266.1212 | G44: 0.0012210012 | H44: 0.28290986 | I44: 16.158779 | J44: 58487.143
A45: [GET] Promotion Page | B45: 817 | C45: 6685 | D45: 245 | E45: 14440 | F45: 2018.7208 | G45: 0.0048959608 | H45: 0.28359676 | I45: 15.244655 | J45: 55044.8
A46: [GET] Tours Page | B46: 812 | C46: 6054 | D46: 150 | E46: 12744 | F46: 1823.1201 | G46: 0.020935961 | H46: 0.28328829 | I46: 14.914878 | J46: 53912.693
A47: [GET] Charters Page | B47: 805 | C47: 4858 | D47: 151 | E47: 12603 | F47: 1870.7561 | G47: 0.034782609 | H47: 0.28229815 | I47: 15.162591 | J47: 55000.335
A48: [GET] Destination Page | B48: 803 | C48: 15998 | D48: 146 | E48: 33313 | F48: 5280.0125 | G48: 0.04607721 | H48: 0.28415334 | I48: 107.23685 | J48: 386448.15
A49: [GET] Airline Tickets Page | B49: 802 | C49: 4536 | D49: 144 | E49: 12161 | F49: 1714.1471 | G49: 0.034912718 | H49: 0.28515059 | I49: 16.838839 | J49: 60469.701
A50: [GET] Search a country | B50: 800 | C50: 4189 | D50: 155 | E50: 9914 | F50: 1196.9086 | G50: 0.03875 | H50: 0.29657046 | I50: 17.624511 | J50: 60854.003
...

Sheet 10 dec
A1: Sample Label | B1: Samples | C1: Average response time (ms) | D1: Min(ms) | E1: Max(ms) | F1: Std. Dev | G1: Error | H1: Throughput | I1: Kb/sec | J1: Avg. Bytes
A2: [GET] Home page | B2: 997 | C2: 10540 | D2: 123 | E2: 22308 | F2: 2932.842 | G2: 0 | H2: 0.10018254 | I2: 99.249838 | J2: 1014466.5 | L2: 100 user 12:15 local time
A3: [GET] Wishlist page | B3: 988 | C3: 3848 | D3: 130 | E3: 23869 | F3: 925.31827 | G3: 0.015182186 | H3: 0.099504181 | I3: 6.9698104 | J3: 71726.492
A4: [GET] Last minute offers | B4: 974 | C4: 5263 | D4: 135 | E4: 18954 | F4: 1659.5508 | G4: 0 | H4: 0.098332537 | I4: 5.7038267 | J4: 59397.619
A5: [GET] Ski page | B5: 973 | C5: 4275 | D5: 154 | E5: 13389 | F5: 1260.7232 | G5: 0.016443988 | H5: 0.0982826 | I5: 5.9703751 | J5: 62204.949
A6: [GET] Promotion Page | B6: 962 | C6: 5548 | D6: 145 | E6: 17259 | F6: 1774.0002 | G6: 0.021829522 | H6: 0.097359129 | I6: 5.7204734 | J6: 60166.57
A7: [GET] Tours Page | B7: 958 | C7: 5220 | D7: 142 | E7: 12104 | F7: 1633.6829 | G7: 0.032359081 | H7: 0.097116246 | I7: 5.6808925 | J7: 59899.699
A8: [GET] Charters Page | B8: 955 | C8: 4007 | D8: 151 | E8: 22526 | F8: 1420.9824 | G8: 0.021989529 | H8: 0.097076138 | I8: 5.7555033 | J8: 60711.473
A9: [GET] Destination Page | B9: 952 | C9: 14381 | D9: 142 | E9: 29266 | F9: 3481.2381 | G9: 0.028361345 | H9: 0.096688736 | I9: 39.688297 | J9: 420326.28
A10: [GET] Airline Tickets Page | B10: 949 | C10: 3876 | D10: 129 | E10: 21356 | F10: 1606.2456 | G10: 0.050579557 | H10: 0.09660861 | I10: 5.7731919 | J10: 61192.77
A11: [GET] Search a country | B11: 928 | C11: 4064 | D11: 126 | E11: 24306 | F11: 1612.9228 | G11: 0.066810345 | H11: 0.094596347 | I11: 5.5976738 | J11: 60594.496
A12: [GET] Search Results (destination) | B12: 918 | C12: 8054 | D12: 131 | E12: 16055 | F12: 2511.6257 | G12: 0 | H12: 0.093828229 | I12: 6.3481218 | J12: 69280.608
A13: [GET] Visit Vacation Details (destination) | B13: 818 | C13: 3412 | D13: 63 | E13: 13229 | F13: 1813.5044 | G13: 0.045232274 | H13: 0.083762805 | I13: 5.7110585 | J13: 69817.67
A14: [GET] Search Results (tours) | B14: 910 | C14: 2475 | D14: 66 | E14: 7505 | F14: 1137.0186 | G14: 0 | H14: 0.093390814 | I14: 5.6451624 | J14: 61897.376
... A19: TOTAL | B19: 28488 | C19: 8841 | D19: 0 | E19: 71609 | F19: 13835.953 | G19: 0.070871946 | H19: 2.8625833 | I19: 265.08172 | J19: 94824.726
A21: 10 useri
A22: [GET] Home page | B22: 50 | C22: 8145 | D22: 7772 | E22: 9930 | F22: 309.44203 | G22: 0 | H22: 0.036241049 | I22: 36.549978 | J22: 1032728.9
A23: [GET] Wishlist page | B23: 50 | C23: 3578 | D23: 3425 | E23: 4030 | F23: 79.370798 | G23: 0 | H23: 0.036363372 | I23: 1.8512174 | J23: 52130.66
A24: [GET] Last minute offers | B24: 50 | C24: 5776 | D24: 4221 | E24: 63171 | F24: 8237.1118 | G24: 0 | H24: 0.036342756 | I24: 1.8846686 | J24: 53102.76
A25: [GET] Ski page | B25: 50 | C25: 3649 | D25: 3472 | E25: 4029 | F25: 101.55994 | G25: 0 | H25: 0.036349889 | I25: 2.1240355 | J25: 59835.46
A26: [GET] Promotion Page | B26: 50 | C26: 4459 | D26: 4237 | E26: 4722 | F26: 91.328263 | G26: 0 | H26: 0.036329605 | I26: 1.9087312 | J26: 53800.22
A27: [GET] Tours Page | B27: 50 | C27: 5423 | D27: 4082 | E27: 63254 | F27: 8261.9542 | G27: 0 | H27: 0.036326253 | I27: 1.8977885 | J27: 53496.72
A28: [GET] Charters Page | B28: 50 | C28: 4574 | D28: 3254 | E28: 62269 | F28: 8242.3609 | G28: 0 | H28: 0.036348912 | I28: 1.9576012 | J28: 55148.38
A29: [GET] Destination Page | B29: 50 | C29: 12333 | D29: 11819 | E29: 12910 | F29: 200.30226 | G29: 0 | H29: 0.036114355 | I29: 13.931041 | J29: 395005.96
A30: [GET] Airline Tickets Page | B30: 50 | C30: 3387 | D30: 3240 | E30: 3534 | F30: 64.602786 | G30: 0 | H30: 0.036357158 | I30: 1.955567 | J30: 55078.58
A31: [GET] Search a country | B31: 50 | C31: 3615 | D31: 3442 | E31: 4341 | F31: 140.53306 | G31: 0 | H31: 0.036351026 | I31: 1.9579742 | J31: 55155.68
A32: [GET] Search Results (destination) | B32: 50 | C32: 7298 | D32: 5723 | E32: 8079 | F32: 510.83139 | G32: 0 | H32: 0.036258421 | I32: 2.1565078 | J32: 60903.48
A33: [GET] Visit Vacation Details (destination) | B33: 50 | C33: 2696 | D33: 2337 | E33: 3070 | F33: 152.53619 | G33: 0 | H33: 0.036396486 | I33: 2.275295 | J33: 64014.48
... A39: TOTAL | B39: 1550 | C39: 8496 | D39: 0 | E39: 64483 | F39: 14035.986 | G39: 0.020645161 | H39: 0.91915253 | I39: 78.998914 | J39: 88010.298
A41: 1 user
A42: [GET] Home page | B42: 3 | C42: 9576 | D42: 8036 | E42: 12525 | F42: 2085.4934 | G42: 0 | H42: 0.013289684 | I42: 13.402958 | J42: 1032728
A43: [GET] Wishlist page | B43: 3 | C43: 3433 | D43: 3418 | E43: 3457 | F43: 17.146428 | G43: 0 | H43: 0.01357761 | I43: 0.69120729 | J43: 52129.667
A44: [GET] Last minute offers | B44: 3 | C44: 6528 | D44: 4408 | E44: 9686 | F44: 2276.1614 | G44: 0 | H44: 0.013456958 | I44: 0.69691885 | J44: 53031.667
A45: [GET] Ski page | B45: 3 | C45: 3511 | D45: 3384 | E45: 3647 | F45: 107.53087 | G45: 0 | H45: 0.013508159 | I45: 0.78932148 | J45: 59835.333
A46: [GET] Promotion Page | B46: 3 | C46: 4350 | D46: 4334 | E46: 4372 | F46: 15.860503 | G46: 0 | H46: 0.013452493 | I46: 0.70676821 | J46: 53799
A47: [GET] Tours Page | B47: 3 | C47: 4124 | D47: 4122 | E47: 4129 | F47: 3.0912062 | G47: 0 | H47: 0.013470432 | I47: 0.70416773 | J47: 53529.667
A48: [GET] Charters Page | B48: 3 | C48: 3372 | D48: 3235 | E48: 3613 | F48: 170.54097 | G48: 0 | H48: 0.01352698 | I48: 0.72757273 | J48: 55077.667
A49: [GET] Destination Page | B49: 3 | C49: 11973 | D49: 11728 | E49: 12258 | F49: 218.09223 | G49: 0 | H49: 0.013020607 | I49: 5.0225848 | J49: 394999
A50: [GET] Airline Tickets Page | B50: 3 | C50: 3266 | D50: 3156 | E50: 3373 | F50: 88.615273 | G50: 0 | H50: 0.013524235 | I50: 0.72742513 | J50: 55077.667
A51: [GET] Search a country | B51: 3 | C51: 3608 | D51: 3493 | E51: 3838 | F51: 162.16521 | G51: 0 | H51: 0.013510653 | I51: 0.72295188 | J51: 54794
...

Sheet 11 dec
A1: Sample Label | B1: Samples | C1: Average response time (ms) | D1: Min(ms) | E1: Max(ms) | F1: Std. Dev | G1: Error | H1: Throughput | I1: Kb/sec | J1: Avg. Bytes
A2: [GET] Home page | B2: 273 | C2: 9668 | D2: 162 | E2: 69430 | F2: 4614.0199 | G2: 0 | H2: 0.28653686 | I2: 277.71062 | J2: 992457.56 | K2: 100 useri 5:50 local time - 15 min
A3: [GET] Wishlist page | B3: 265 | C3: 3752 | D3: 262 | E3: 6898 | F3: 820.78784 | G3: 0.033962264 | H3: 0.28539735 | I3: 20.162362 | J3: 72342.155
A4: [GET] Last minute offers | B4: 259 | C4: 3939 | D4: 216 | E4: 61068 | F4: 3659.7979 | G4: 0 | H4: 0.28328798 | I4: 18.662892 | J4: 67460.687
A5: [GET] Ski page | B5: 254 | C5: 4351 | D5: 149 | E5: 64653 | F5: 3940.0661 | G5: 0.043307087 | H5: 0.28166015 | I5: 18.298753 | J5: 66526.709
A6: [GET] Promotion Page | B6: 249 | C6: 5190 | D6: 164 | E6: 10148 | F6: 1534.2544 | G6: 0.040160643 | H6: 0.27989667 | I6: 16.434401 | J6: 60125.141
A7: [GET] Tours Page | B7: 241 | C7: 4872 | D7: 202 | E7: 8679 | F7: 1486.5664 | G7: 0.062240664 | H7: 0.27542228 | I7: 16.322991 | J7: 60687.693
A8: [GET] Charters Page | B8: 229 | C8: 3618 | D8: 182 | E8: 7479 | F8: 828.95345 | G8: 0.026200873 | H8: 0.26695671 | I8: 17.421291 | J8: 66825.074
A9: [GET] Destination Page | B9: 227 | C9: 13789 | D9: 175 | E9: 66871 | F9: 6381.6999 | G9: 0.066079295 | H9: 0.26553031 | I9: 110.98145 | J9: 427992.6
A10: [GET] Airline Tickets Page | B10: 222 | C10: 3546 | D10: 172 | E10: 7756 | F10: 1269.5699 | G10: 0.099099099 | H10: 0.27018968 | I10: 19.636383 | J10: 74420.518
A11: [GET] Search a country by name | B11: 202 | C11: 4341 | D11: 166 | E11: 63302 | F11: 4362.9806 | G11: 0.11881188 | H11: 0.24973234 | I11: 20.06519 | J11: 82275.104
A12: [GET] Destination Details for Country | B12: 196 | C12: 5749 | D12: 145 | E12: 65821 | F12: 4777.2819 | G12: 0.10714286 | H12: 0.24593177 | I12: 19.973888 | J12: 83166.403
A13: [GET] Visit Vacation Details (country) | B13: 171 | C13: 3073 | D13: 150 | E13: 7349 | F13: 1476.3831 | G13: 0.24561404 | H13: 0.21931878 | I13: 18.603529 | J13: 86859.93
A14: [POST] Search Filters (destination) | B14: 200 | C14: 182 | D14: 137 | E14: 669 | F14: 80.754039 | G14: 0.11 | H14: 0.26185311 | I14: 0.2386162 | J14: 933.13
... A33: TOTAL | B33: 6257 | C33: 3558 | D33: 0 | E33: 69430 | F33: 4213.4906 | G33: 0.051782004 | H33: 6.5388438 | I33: 670.05889 | J33: 104932.97
A35: 300 useri 6:15 - 7:05 local
A36: [GET] Home page | B36: 1522 | C36: 72046 | D36: 133 | E36: 174317 | F36: 45569.458 | G36: 0 | H36: 0.5004615 | I36: 392.07961 | J36: 802238.58
A37: [GET] Wishlist page | B37: 1478 | C37: 7947 | D37: 143 | E37: 63479 | F37: 5668.0456 | G37: 0.19959405 | H37: 0.49478517 | I37: 117.0065 | J37: 242154.9
A38: [GET] Last minute offers | B38: 1468 | C38: 6383 | D38: 145 | E38: 61147 | F38: 5679.2636 | G38: 0 | H38: 0.49489012 | I38: 55.347402 | J38: 114521.86
A39: [GET] Ski page | B39: 1458 | C39: 10294 | D39: 143 | E39: 29518 | F39: 6728.7426 | G39: 0.23182442 | H39: 0.49214957 | I39: 38.960218 | J39: 81063.29
A40: [GET] Promotion Page | B40: 1452 | C40: 24346 | D40: 59 | E40: 72310 | F40: 17716.45 | G40: 0.21349862 | H40: 0.48935963 | I40: 33.790368 | J40: 70707.379
A41: [GET] Tours Page | B41: 1435 | C41: 21754 | D41: 164 | E41: 66066 | F41: 14635.487 | G41: 0.20139373 | H41: 0.48631424 | I41: 34.759746 | J41: 73191.317
A42: [GET] Charters Page | B42: 1420 | C42: 4161 | D42: 152 | E42: 61780 | F42: 3195.1654 | G42: 0.22464789 | H42: 0.48804312 | I42: 32.025227 | J42: 67194.539
A43: [GET] Destination Page | B43: 1418 | C43: 46256 | D43: 143 | E43: 104962 | F43: 31846.768 | G43: 0.19464034 | H43: 0.48276959 | I43: 188.85703 | J43: 400583.63
A44: [GET] Airline Tickets Page | B44: 1395 | C44: 4397 | D44: 27 | E44: 60498 | F44: 2867.132 | G44: 0.19713262 | H44: 0.48569227 | I44: 34.712675 | J44: 73185.803
A45: [GET] Search a country by name | B45: 1116 | C45: 7998 | D45: 137 | E45: 21341 | F45: 5696.8174 | G45: 0.30555556 | H45: 0.38911469 | I45: 24.949471 | J45: 65657.4
A46: [GET] Destination Details for Country | B46: 1113 | C46: 26919 | D46: 130 | E46: 83775 | F46: 18128.687 | G46: 0.23180593 | H46: 0.38640145 | I46: 28.224076 | J46: 74796.443
A47: [GET] Visit Vacation Details (country) | B47: 953 | C47: 15799 | D47: 126 | E47: 59924 | F47: 11252.651 | G47: 0.35257083 | H47: 0.33370906 | I47: 27.749426 | J47: 85150.255
... A67: TOTAL | B67: 33836 | C67: 13965 | D67: 0 | E67: 174317 | F67: 23399.819 | G67: 0.19225086 | H67: 11.125897 | I67: 1184.0491 | J67: 108976.95
A69: 10 useri
A70: [GET] Home page | B70: 20 | C70: 9107 | D70: 8267 | E70: 10132 | F70: 492.4468 | G70: 0 | H70: 0.048079581 | I70: 48.526254 | J70: 1033513.2
A71: [GET] Wishlist page | B71: 20 | C71: 3540 | D71: 3376 | E71: 3707 | F71: 73.838676 | G71: 0 | H71: 0.048795245 | I71: 2.486001 | J71: 52170.35
A72: [GET] Last minute offers | B72: 20 | C72: 3552 | D72: 3490 | E72: 3689 | F72: 52.711005 | G72: 0 | H72: 0.048797507 | I72: 2.86789 | J72: 60181.75
A73: [GET] Ski page | B73: 20 | C73: 3714 | D73: 3531 | E73: 3948 | F73: 87.503414 | G73: 0 | H73: 0.04879465 | I73: 2.8636098 | J73: 60095.45
A74: [GET] Promotion Page | B74: 20 | C74: 4652 | D74: 4286 | E74: 4871 | F74: 159.64269 | G74: 0 | H74: 0.049470786 | I74: 2.6170602 | J74: 54170.75
A75: [GET] Tours Page | B75: 10 | C75: 4485 | D75: 4320 | E75: 4703 | F75: 137.22569 | G75: 0 | H75: 1.6056519 | I75: 83.35262 | J75: 53157.9
A76: [GET] Charters Page | B76: 10 | C76: 3308 | D76: 3188 | E76: 3437 | F76: 64.816973 | G76: 0 | H76: 1.9627085 | I76: 105.74188 | J76: 55168.5
A77: [GET] Destination Page | B77: 10 | C77: 12757 | D77: 12262 | E77: 13163 | F77: 259.08649 | G77: 0 | H77: 0.67118599 | I77: 259.86892 | J77: 396471
A78: [GET] Airline Tickets Page | B78: 10 | C78: 3344 | D78: 3260 | E78: 3517 | F78: 70.697171 | G78: 0 | H78: 1.8921476 | I78: 101.94038 | J78: 55168.5
A79: [GET] Search a country by name | B79: 10 | C79: 3550 | D79: 3457 | E79: 3787 | F79: 99.133294 | G79: 0.2 | H79: 1.9451469 | I79: 104.05947 | J79: 54780.9
...
